Workbook

Sheet Datin_Prov
A1: DATA KEBERADAAN UPTD PPA TINGKAT PROVINSI
A3: No | B3: Provinsi | C3: Ortala | E3: Asdep Tata Kelola | H3: Kesimpulan
C4: Status | D4: Dasar Pembentukan | E4: Status | F4: Status | G4: Dasar Pembentukan
A5: 1 | B5: Provinsi Aceh | C5: Ada | D5: Peraturan Gubernur Aceh Nomor 59 Tahun 2019 tentang Kedudukan, Susunan Organisasi, Tugas, Fungsi dan Tata Kerja Unit Pelaksana Teknis Daerah Perlindungan Perempuan dan Anak pada Dinas Pemberdayaan Perempuan dan Perlindungan Anak Aceh | E5: UPTD PPA | F5: Ada | G5: Peraturan Gubernur Aceh No. 59 | H5: Ada UPTD | J5: Jumlah Provinsi menurut keberadaan UPTD PPA
A6: 2 | B6: Provinsi Sumatera Utara | C6: Ada | D6: Peraturan Gubernur Sumatera Utara Nomor 28 Tahun 2023 tentang Perubahan atas Peraturan Gubernur Sumatera Utara Nomor 9 Tahun 2023 tentang Susunan Organisasi Perangkat Daerah | E6: UPTD PPA | F6: Ada | G6: Peraturan Gubernur Sumatera Utara Nomor 28 Tahun 2023 tentang Perubahan atas Peraturan Gubernur Sumatera Utara Nomor 9 Tahun 2023 tentang Susunan Organisasi Perangkat Daerah | H6: Ada UPTD | J6: Kategori | K6: Jumlah
A7: 3 | B7: Provinsi Sumatera Barat | C7: Ada | D7: Peraturan Gubernur Sumatera Barat Nomor 90 Tahun 2020 tentang Pembentukan Organisasi Dan Tata Kerja Unit Pelaksana Teknis Daerah Dinas Pemberdayaan Perempuan Dan Perlindungan Anak, Pengendalian Penduduk Dan Keluarga Berencana Provinsi Sumatera Barat yang merubah/mencabut Peraturan Gubernur Sumatera Barat Nomor 99 Tahun 2017 tentang Pembentukan UPTD PPA | E7: #N/A | F7: Tidak Ada | G7: #N/A | H7: Ada UPTD | J7: Ada | K7: 34 | L7: =K7/K9 -> 0.89473684
A8: 4 | B8: Provinsi Riau | C8: Ada | D8: Peraturan Gubernur Provinsi Riau Nomor 85 Tahun 2019 | E8: UPT PPA | F8: Ada | G8: Peraturan Gubernur Nomor 56 Tahun 2017 | H8: Ada UPTD | J8: Tidak Ada | K8: 4
A9: 5 | B9: Provinsi Jambi | C9: Ada | D9: Peraturan Gubernur Provinsi Jambi Nomor 61 Tahun 2018 | E9: UPTD PPA | F9: Ada | G9: Peraturan Gubernur Provinsi Jambi Nomor 61 Tahun 2018 Tahun 2018 | H9: Ada UPTD | J9: Total | K9: 38
A10: 6 | B10: Provinsi Sumatera Selatan | C10: Ada | D10: Peraturan Gubernur Sumatera Selatan Nomor 54 Tahun 2020 tentang Pembentukan, Uraian Tugas dan Fungsi Unit Pelaksana Teknis Dinas Perlindungan Perempuan dan Anak pada Dinas Pemberdayaan Perempuan dan Perlindungan Anak Provinsi Sumatera Selatan | E10: UPTD PPA | F10: Ada | G10: Peraturan Gubernur No. 54 Tahun 2020 | H10: Ada UPTD
A11: 7 | B11: Provinsi Bengkulu | C11: Ada | D11: Peraturan Gubernur Bengkulu Nomor 34 Tahun 2017 | E11: UPTD PPA | F11: Ada | G11: Peraturan Gubernur Bengkulu Nomor 34 Tahun 2017 | H11: Ada UPTD
A12: 8 | B12: Provinsi Lampung | C12: Ada | D12: Peraturan Gubernur Lampung Nomor 10 Tahun 2020 tentang Pembentukan Organisasi dan Tata Kerja Unit Pelaksana Teknis Dinas (UPTD) pada Dinas Daerah Provinsi Lampung | E12: UPTD PPA | F12: Ada | G12: Peraturan Gubernur Lampung Nomor 10 Tahun 2020 tentang Pembentukan Organisasi dan Tata Kerja Unit Pelaksana Teknis Dinas (UPTD) pada Dinas Daerah Provinsi Lampung | H12: Ada UPTD
A13: 9 | B13: Provinsi Kepulauan Bangka Belitung | C13: Ada | D13: Peraturan Gubernur Kepulauan Bangka Belitung Nomor 12 Tahun 2021 | E13: UPTD PPA | F13: Ada | G13: Pergub No. 12 Tahun 2021 | H13: Ada UPTD
A14: 10 | B14: Provinsi Kepulauan Riau | C14: Ada | D14: Peraturan Gubernur Provinsi Kepulauan Riau Nomor 81 Tahun 2017 tentang Pembentukan UPTD PPA, merubah/mencabut Peraturan Gubernur Provinsi Kepulauan Riau Nomor 81 Tahun 2017 tentang Pembentukan Unit Pelaksana Teknis Pusat Pelayanan Terpadu Perlindungan Perempuan dan Anak Pada Dinas Pemberdayaan Perempuan, Perlindungan Anak, Pengendalian Penduduk dan Keluarga Berencana Provinsi Kepulauan Riau | E14: #N/A | F14: Tidak Ada | G14: #N/A | H14: Ada UPTD
A15: 11 | B15: Provinsi Dki Jakarta | C15: Ada | D15: Peraturan Gubernur DKI Jakarta Nomor 397 Tahun 2016 tentang Pembentukan Organisasi dan Tata Kerja Pusat Pelayanan Terpadu Pemberdayaan Perempuan dan Anak Peraturan Gubernur DKI Jakarta Nomor 57 Tahun 2022 tentang Organisasi dan Tata Kerja Perangkat Daerah | E15: UPT PPPA | F15: Ada | G15: Peraturan Gubernur DKI Jakarta Nomor 397 Tahun 2016 tentang Pembentukan Organisasi dan Tata Kerja Pusat Pelayanan Terpadu Pemberdayaan Perempuan dan Anak Peraturan Gubernur DKI Jakarta Nomor 57 Tahun 2022 tentang Organisasi dan Tata Kerja Perangkat Daerah | H15: Ada UPTD
A16: 12 | B16: Provinsi Jawa Barat | C16: Ada | D16: Peraturan Gubernur Jawa Barat Nomor 64 Tahun 2019 tentang Tugas Pokok, Fungsi, Rincian Tugas Unit dan Tata Kerja UPTD di Lingkungan DP3AKB Pemerintah Daerah Provinsi Jawa Barat | E16: UPTD PPA | F16: Ada | G16: Peraturan Gubernur Jawa Barat Nomor 64 Tahun 2019 tentang Tugas Pokok, Fungsi, Rincian Tugas Unit dan Tata Kerja UPTD di Lingkungan DP3AKB Pemerintah Daerah Provinsi Jawa Barat | H16: Ada UPTD
A17: 13 | B17: Provinsi Jawa Tengah | C17: Ada | D17: Peraturan Gubernur Jawa Tengah Nomor 15 Tahun 2023 tentang Organisasi dan Tata Kerja Dinas Pemberdayaan Perempuan, Perlindungan Anak, Pengendalian Penduduk dan Keluarga Berencana Provinsi Jawa Tengah | E17: UPTD PPA Provinsi Jawa Tengah | F17: Ada | G17: Peraturan Gubernur Jawa Tengah Nomor 15 Tahun 2023 tentang Organisasi dan Tata Kerja Dinas Pemberdayaan Perempuan, Perlindungan Anak, Pengendalian Penduduk, dan Keluarga Berencana Provinsi Jawa Tengah | H17: Ada UPTD
A18: 14 | B18: Provinsi Daerah Istimewa Yogyakarta | C18: Ada | D18: Peraturan Gubernur (Pergub) Provinsi Daerah Istimewa Yogyakarta Nomor 11 Tahun 2022 tentang Pembentukan, Susunan Organisasi, Tugas, Fungsi, dan Tata Kerja Unit Pelaksana Teknis pada Dinas Pemberdayaan Perempuan, Perlindungan Anak, dan Pengendalian Penduduk | E18: BALAI PPA | F18: Ada | G18: Peraturan Gubernur (Pergub) Provinsi Daerah Istimewa Yogyakarta Nomor 11 Tahun 2022 tentang Pembentukan, Susunan Organisasi, Tugas, Fungsi, dan Tata Kerja Unit Pelaksana Teknis pada Dinas Pemberdayaan Perempuan, Perlindungan Anak, dan Pengendalian Penduduk | H18: Ada UPTD
A19: 15 | B19: Provinsi Jawa Timur | C19: Ada | D19: Peraturan Gubernur Jawa Timur Nomor 1 Tahun 2021 | E19: UPT PPA | F19: Ada | G19: Peraturan Gubernur Jawa Timur Nomor 1 Tahun 2021 | H19: Ada UPTD
A20: 16 | B20: Provinsi Banten | C20: Ada | D20: Peraturan Gubernur Banten Nomor 55 Tahun 2021 | E20: UPTD PPA | F20: Ada | G20: Peraturan Gubernur No 55 Tahun 2021 | H20: Ada UPTD
A21: 17 | B21: Provinsi Bali | C21: Ada | D21: Peraturan Gubernur Bali Nomor 59 Tahun 2019 tentang Pembentukan Unit Pelaksana Teknis Daerah di Lingkungan Pemerintah Provinsi Bali | E21: UPTD PPA | F21: Ada | G21: Pergub Nomor 59 Tahun 2019 | H21: Ada UPTD
A22: 18 | B22: Provinsi Nusa Tenggara Barat | C22: Ada | D22: Peraturan Gubernur NTB Nomor 30 tahun 2019 tentang perubahan kedua atas peraturan gubernur nomor 29 tahun 2018 tentang pembentukan, kedudukan, susunan organisasi tugas dan fungsi serta tata kerja unit pelaksana teknis dinas pada dinas-dinas daerah dan unit pelaksana teknis badan pada badan-badan daerah provinsi NTB | E22: #N/A | F22: Tidak Ada | G22: #N/A | H22: Ada UPTD
A23: 19 | B23: Provinsi Nusa Tenggara Timur | C23: Ada | D23: Peraturan Gubernur (Pergub) Provinsi Nusa Tenggara Timur Nomor 49 Tahun 2022 tentang Kedudukan, Susunan Organisasi, Tugas dan Fungsi serta Tata Kerja Cabang Dinas dan Unit Pelaksana Teknis Daerah Provinsi Nusa Tenggara Timur | E23: UPTD PPA | F23: Ada | G23: Peraturan Gubernur (Pergub) Provinsi Nusa Tenggara Timur Nomor 49 Tahun 2022 tentang Kedudukan, Susunan Organisasi, Tugas dan Fungsi serta Tata Kerja Cabang Dinas dan Unit Pelaksana Teknis Daerah Provinsi Nusa Tenggara Timur | H23: Ada UPTD
A24: 20 | B24: Provinsi Kalimantan Barat | C24: Ada | D24: Peraturan Gubernur (Pergub) Provinsi Kalimantan Barat Nomor 101 Tahun 2020 tentang Pembentukan, Susunan Organisasi, Tugas dan Fungsi serta Tata Kerja Unit Pelaksana Teknis Perlindungan Perempuan dan Anak Provinsi Kalimantan Barat | E24: UPT PPA Provinsi Kalimantan Barat | F24: Ada | G24: Peraturan Gubernur (Pergub) Provinsi Kalimantan Barat Nomor 101 Tahun 2020 tentang Pembentukan, Susunan Organisasi, Tugas dan Fungsi serta Tata Kerja Unit Pelaksana Teknis Perlindungan Perempuan dan Anak Provinsi Kalimantan Barat | H24: Ada UPTD
A25: 21 | B25: Provinsi Kalimantan Tengah | C25: Ada | D25: Peraturan Gubernur Kalimantan Tengah Nomor 20 Tahun 2019 tentang Pembentukan Susunan Organisasi. Tugas, Fungsi da Tata Kerja UPT PPA pada Dinas P3AP2KB | E25: UPT PPA | F25: Ada | G25: Peraturan Gubernur Nomor 2019 dan Peraturan Gubernur Nomor 48 Tahun 2023 | H25: Ada UPTD
A26: 22 | B26: Provinsi Kalimantan Selatan | C26: Ada | D26: Peraturan Gubernur Kalimantan Selatan Nomor 073 Tahun 2019 tentang Pembentukan Organisasi dan Tata Kerja UPTD PPA pada DP3A | E26: UPTD Perlindungan Perempuan dan Anak Provinsi Kalimantan Selatan | F26: Ada | G26: Peraturan Gubernur (Pergub) Provinsi Kalimantan Selatan Nomor 73 Tahun 2019 tentang Pembentukan, Organisasi, Dan Tata Kerja Unit Pelaksana Teknis Daerah Perlindungan Perempuan Dan Anak Pada Dinas Pemberdayaan Perempuan Dan Perlindungan Anak Provinsi Kalimantan Selatan | H26: Ada UPTD
A27: 23 | B27: Provinsi Kalimantan Timur | C27: Ada | D27: Peraturan Gubernur Kalimantan Timur No. 37 Tahun 2020 | E27: UPTD PPA | F27: Ada | G27: Peraturan Gubernur Provinsi Kalimantan Timur Nomor 37 Tahun 2020 Pembentukan dan Susunan Organisasi Unit Pelaksana Teknis Daerah Perlindungan Perempuan dan Anak Pada Dinas Kependudukan, Pemberdayaan Perempuan dan Perlindungan Anak Provinsi Kalimantan Timur | H27: Ada UPTD
A28: 24 | B28: Provinsi Kalimantan Utara | C28: Ada | D28: Peraturan Gubernur Nomor 1 Tahun 2019 Tanggal 2 Januari 2019 tentang Organisasi dan Tata Kerja UPT pada Dinas PPPAPPKB Provinsi Kalimantan Utara | E28: UPTD PPA | F28: Ada | G28: Peraturan Gubernur Nomor 1 Tahun 2019 Tanggal 2 Januari 2019 tentang Organisasi dan Tata Kerja UPT pada Dinas PPPAPPKB Provinsi Kalimantan Utara | H28: Ada UPTD
A29: 25 | B29: Provinsi Sulawesi Utara | C29: Ada | D29: Peraturan Gubernur (Pergub) Provinsi Sulawesi Utara Nomor 12 Tahun 2022 tentang Kedudukan, Susunan Organisasi, Tugas dan Fungsi serta Tata Kerja Perangkat Daerah | E29: UPTD PPA | F29: Ada | G29: Peraturan Gubernur Sulawesi Utara Nomor 31 Tahun 2020 tentang Pembentukan Unit Pelaksana Teknis Daerah Pada Dinas Pemberdayaan Perempuan dan Perlindungan Anak Daerah Provinsi Tipe A Provinsi Sulawesi Utara | H29: Ada UPTD
A30: 26 | B30: Provinsi Sulawesi Tengah | C30: Ada | D30: Peraturan Gubernur Sulawesi Tengah Nomor 48 Tahun 2020 | E30: #N/A | F30: Tidak Ada | G30: #N/A | H30: Ada UPTD
A31: 27 | B31: Provinsi Sulawesi Selatan | C31: Ada | D31: Peraturan Gubernur Sulawesi Selatan No 19 Tahun 2018 tentang Organisasi dan Tata Kerja Unit Pelaksana Teknis Pusat Pelayanan Terpadu Perlindungan Perempuan dan Anak (UPT P2TP2A) pada Dinas PPPA Provinsi Sulawesi Selatan | E31: UPT PPA | F31: Ada | G31: Peraturan Gubernur Sulawesi Selatan No. 53 Tahun 2020 | H31: Ada UPTD
A32: 28 | B32: Provinsi Sulawesi Tenggara | C32: Ada | D32: Peraturan Gubernur Sulawesi Tenggara Nomor 22 Tahun 2024 | E32: UPTD PPA | F32: Ada | G32: Peraturan Gubernur Sulawesi Tenggara Nomor 71 Tahun 2017 tentang Pembentukan, Kedudukan, Susunan Organisasi, Tugas dan Fungsi Serta Tata Kerja Unit Pelaksana Teknis Dinas Pada Dinas Pemberdayaan Perempuan, Perlindungan Anak, Pengendalian Penduduk dan Keluarga Berencana Provinsi Sulawesi Tenggara (Lembaran Daerah Provinsi Sulawesi Tenggara Tahun 2017 Nomor 71) sebagaimana telah diubah dengan Peraturan Gubernur Sulawesi Tenggara Nomor 22 Tahun 2024 Tentang Perubahan atas Peraturan Gubernur Sulawesi Tenggara Nomor 71 Tahun 2017 tentang Pembentukan, Kedudukan, Susunan Organisasi, Tugas dan Fungsi Serta Tata Kerja Unit Pelaksana Teknis Dinas Pada Dinas Pemberdayaan Perempuan, Perlindungan Anak, Pengendalian Penduduk dan Keluarga Berencana Provinsi Sulawesi Tenggara | H32: Ada UPTD
A33: 29 | B33: Provinsi Gorontalo | C33: Ada | D33: Peraturan Gubernur Gorontalo Nomor 15 Tahun 2024 tentang Pembentukan, Kedudukan, Susunan organisasi, Tugas dan Fungsi serta tata kerja UPTDPPA, dan UPTD lain di Provinsi Gorontalo | E33: UPTD PPA | F33: Ada | G33: Peraturan Gubernur Gorontalo Nomor 15 Tahun 2024 tentang Pembentukan, Kedudukan, Susunan organisasi, Tugas dan Fungsi serta tata kerja UPTDPPA, dan UPTD lain di Provinsi Gorontalo | H33: Ada UPTD
A34: 30 | B34: Provinsi Sulawesi Barat | C34: Ada | D34: Peraturan Gubernur Sulawesi Barat Nomor 36 Tahun 2018 tentang Perubahan atas Peraturan Gubernur Sulawesi Barat Nomor 41 Tahun 2017 tentang Fungsi dan Tata Kerja Cabang Dinas dan Unit Pelaksana Teknis Daerah (UPTD) Provinsi Sulawesi Barat | E34: UPTD PPA | F34: Ada | G34: Peraturan Gubernur Sulawesi Barat Nomor 36 Tahun 2018 Tentang Perubahan atas Peraturan Gubernur Sulawesi Barat No. 41 Tahun 2017 tentang Fungsi dan Tata Kerja Cabang Dinas dan Unit Pelaksana Tekhnis Daerah (UPTD) Provinsi Sulawesi Barat | H34: Ada UPTD
A35: 31 | B35: Provinsi Maluku | C35: Ada | D35: Peraturan Gubernur Maluku Nomor 19 Tahun 2022 | E35: UPTD PPA | F35: Ada | G35: Peraturan Gubernur Maluku Nomor 19 Tahun 2022 | H35: Ada UPTD
A36: 32 | B36: Provinsi Maluku Utara | C36: Ada | D36: Peraturan Gubernur Maluku Utara Nomor 29 Tahun 2020 tentang Pembentukan UPTD PPA Provinsi Maluku Utara | E36: UPTD PPA | F36: Ada | G36: Peraturan Gubernur Maluku Utara Nomor 29 Tahun 2020 tentang Pembentukan UPTD PPA Provinsi Maluku Utara | H36: Ada UPTD
A37: 33 | B37: Provinsi Papua Barat | C37: Ada | D37: Peraturan Gubernur Papua Barat Nomor : 16 Tahun 2021 tentang Pembentukan Unit Pelaksana Teknis Daerah Perlindungan Perempuan dan Anak pada Dinas Pemberdayaan Perempuan dan Perlindungan Anak Prov. Papua Barat | E37: #N/A | F37: Tidak Ada | G37: #N/A | H37: Ada UPTD
A38: 34 | B38: Provinsi Papua Barat Daya | C38: Tidak Ada | D38: 0 | E38: #N/A | F38: Tidak Ada | G38: #N/A | H38: Tidak Ada UPTD
A39: 35 | B39: Provinsi PAPUA | C39: Ada | D39: Peraturan Gubernur Papua Nomor 13 Tahun 2025 tentang Perubahan atas Peraturan Gubernur Papua Nomor 42 Tahun 2024 tentang Organisasi dan Tata Kerja Unit Pelaksana Teknis Daerah pada Dinas Pemberdayaan Perempuan, Perlindungan Anak dan Keluarga Berencana | E39: 0 | F39: Ada | G39: Peraturan Gubernur Papua Nomor 13 Tahun 2025 tentang Perubahan atas Peraturan Gubernur Papua Nomor 42 Tahun 2024 tentang Organisasi dan Tata Kerja Unit Pelaksana Teknis Daerah pada Dinas Pemberdayaan Perempuan, Perlindungan Anak dan Keluarga Berencana | H39: Ada UPTD
A40: 36 | B40: Provinsi Papua Selatan | C40: Tidak Ada | D40: Peraturan Gubernur Papua Selatan | E40: UPTD PPA | F40: Ada | G40: PERATURAN GUBERNUR PAPUA SELATAN | H40: Tidak Ada UPTD
A41: 37 | B41: Provinsi Papua Tengah | C41: Tidak Ada | D41: 0 | E41: #N/A | F41: Tidak Ada | G41: #N/A | H41: Tidak Ada UPTD
...

Sheet UPTD PPA Provinsi
A1: NO | B1: PROVINSI | C1: NAMA KEPALA UPTD | D1: ALAMAT KANTOR | E1: NO. TELP KANTOR UPTD PPA | F1: NO. HOTLINE LAYANAN UPTD | G1: NOMENKLATUR | H1: Dasar Pembentukan | I1: TAHUN (Dasar Pembentukan) | J1: KELAS UPTD | K1: CONTACT PERSON | L1: EMAIL | M1: STRUKTUR ORGANISASI UPTD PPA | N1: KETERSEDIAAN GEDUNG/KANTOR UPTD YANG TERPISAH DARI DINAS | O1: KETERSEDIAAN RUMAH PERLINDUNGAN | P1: KETERANGAN | Q1: KEBIJAKAN STANDAR PELAYANAN | R1: Ketersediaan | AB1: IMPLEMENTASI 11 TUGAS UPTD PPA PROVINSI DAN KABUPATEN/KOTA SESUAI UU NOMOR 12 TAHUN 2022 DAN PERATURAN PRESIDEN NOMOR 55 TAHUN 2024 | AM1: KET | AN1: JUMLAH KASUS YANG DITANGANI TAHUN 2024 | AO1: JENIS KEKERASAN YANG PALING BANYAK DITANGANI | AP1: Tahun Pembentukan Berdasarkan Perkada | AY1: Tantangan yang Dihadapi dalam Pemberian Layanan | AZ1: Usulan Mekanisme Pelayanan Perempuan dan Anak Korban Kekerasan yang Efektif | BA1: Jumlah Layanan Yang Sudah Diberikan | BB1: Tantangan Yang Dihadapi | BG1: Jumlah UPTD PPA Provinsi: | BH1: Kepemilikian | BJ1: Kelengkapan
R2: Survei Kepuasan Masyarakat (SKM) | S2: Maklumat Pelayanan | T2: Psikolog Klinis | U2: Pekerja Sosial | V2: Analis Hukum | W2: Mediator Tersertifikasi | X2: Konselor Hukum | Y2: Konselor Psikologi | Z2: Ketersediaan JF Lain yang sesuai dengan Keputusan MenpanRB Nomor 998/2021 | AA2: Jabfung Lain | AB2: (1) menerima laporan atau penjangkauan korban | AC2: (2) memberikan informasi tentang hak korban | AD2: (3) memfasilitasi pemberian layanan kesehatan | AE2: (4) memfasilitasi pemberian layanan penguatan psikologis | AF2: (5) memfasilitasi pemberian layanan psikososial, rehabilitasi sosial, pemberdayaan sosial, dan reintegrasi sosial | AG2: (6) menyediakan layanan hukum | AH2: (7) mengidentifikasi kebutuhan pemberdayaan ekonomi | AI2: (8) mengidentifikasi kebutuhan penampungan sementara untuk korban dan keluarga korban yang perlu dipenuhi segera | AJ2: (9) memfasilitasi kebutuhan korban penyandang disabilitas | AK2: (10) mengoordinasikan dan bekerja sama atas pemenuhan hak korban dengan lembaga lainnya | AL2: (11) memantau pemenuhan hak korban oleh aparatur penegak hukum selama proses secara peradilan | AP2: 2016 | AQ2: 2017 | AR2: 2018 | AS2: 2019 | AT2: 2020 | AU2: 2021 | AV2: 2022 | AW2: 2023 | AX2: 2024 | BH2: Gedung Sendiri | BI2: Rumah Perlindungan | BJ2: Kebijakan Pelayanan | BK2: SDM
A3: (1) | B3: (2) | C3: (3) | D3: (4) | E3: (5) | F3: (6) | G3: (7) | H3: (8) | I3: (9) | J3: (10) | K3: (11) | L3: (12) | M3: (13) | N3: (14) | O3: (15) | P3: (16) | Q3: (17) | R3: (18) | S3: (19) | T3: (20) | U3: (21) | V3: (22) | W3: (23) | X3: (24) | Y3: (25) | Z3: (26) | AA3: (27) | AB3: (28) | AC3: (29) | AD3: (30) | AE3: (31) | AF3: (32) | AG3: (33) | AH3: (34) | AI3: (35) | AJ3: (36) | AK3: (37) | AL3: (38) | AM3: (39) | AN3: (40) | AO3: (41) | AP3: (42) | AQ3: (43) | AR3: (44) | AS3: (45) | AT3: (46) | AU3: (47) | AV3: (48) | AW3: (49) | AX3: (50) | AY3: (51) | AZ3: (52) | BA3: (53) | BB3: 1 | BC3: 2 | BD3: 3 | BE3: 4 | BF3: 5 | BG3: =countif(BG4:BG41,"Ada") -> 34
A4: 1 | B4: PROVINSI ACEH | C4: Faula Mardalya, SE (Plt) | D4: Jln Tgk. Batee Timoh No 2 Gampong Jeulingke Kec. Syiah Kuala Kota Banda Aceh | E4: 0 | F4: 8116808875 | G4: UPTD PPA | H4: Peraturan Gubernur Aceh No. 59 | I4: 2019 | J4: A | K4: 85358263555 | L4: faula.mardalya@gmail.com | M4: Kepala UPTD, Kasubbag TU, Kasi Penerimaan dan Klarifikasi, Kasi Tindak Lanjut Kasus, Analis Hukum, Pekerja Sosial, Penyuluh Sosial, Psikolog Klinis/Forensik | N4: Mandiri | O4: Milik Sendiri | Q4: Ada | R4: Ada | S4: Ada | T4: Ada | U4: Ada | V4: Ada | W4: Ada | X4: Ada | Y4: Ada | Z4: Tidak Ada | AA4: Ada | AB4: Sudah | AC4: Sudah | AD4: Sudah | AE4: Sudah | AF4: Sudah | AG4: Sudah | AH4: Sudah | AI4: Sudah | AJ4: Belum | AK4: Sudah | AL4: Sudah | AN4: 173 | AO4: KDRT, Pemorkosaan, Pelecehan Seksual dan Kekerasan Fisik, penelantaran nafkah anak | AS4: v | AY4: Belum tersedianya jabatan Psikolog Klinis yang ditempatkan di uptd ppa baik PNS maupun P3K | AZ4: Penanganan pengaduan langsung/tidak langsung Penjangkauan korban Mekanisme rujukan Pendampingan korban Reintegrasi | BA4: =countif(AB4:AL4,"Sudah") -> 10 | BG4: =IFERROR(__xludf.DUMMYFUNCTION("IF(REGEXMATCH(H4,""Peraturan Gubernur""),""Ada"",""Tidak Ada"")"),"Ada") -> Ada | BH4: =IF(N4 = "Belum Punya", "Tidak Ada", IF(N4 = "", "Tidak Menjawab", "Ada")) -> Ada | BI4: =IF(O4 = "Tidak Punya", "Tidak Ada", IF(O4 = "", "Tidak Menjawab", "Ada")) -> Ada | BJ4: =IF(AND(Q4="Ada",R4="Ada",S4="Ada"),"Lengkap","Tidak Lengkap") -> Lengkap | BK4: =IF(AND(T4="Ada",U4="Ada",V4="Ada",W4="Ada",X4="Ada",Y4="Ada"),"Lengkap","Tidak Lengkap") -> Lengkap
A5: 2 | B5: PROVINSI SUMATERA UTARA | C5: Susiana Hendrayani, S.Pt, M.Si | D5: Jln. Iskandar Muda No. 272 Medan | E5: - | F5: - | G5: UPTD PPA | H5: Peraturan Gubernur Sumatera Utara Nomor 28 Tahun 2023 tentang Perubahan atas Peraturan Gubernur Sumatera Utara Nomor 9 Tahun 2023 tentang Susunan Organisasi Perangkat Daerah | I5: 2023 | J5: A | K5: Amri (Kasi Tindak Lanjut) 081361694001 Widya (Kasi Pengaduan) 081361680791 | L5: uptdppa.provsu@gmail.com | M5: 1. Kepala UPTD 2. Kepala Seksi Pengaduan 3. Kepala Seksi Tindak Lanjut 4. Kasubag TU | N5: Mandiri | O5: Milik Sendiri | P5: Milik Pemerintah Daerah | Q5: Ada | R5: Ada | S5: Ada | T5: Ada | U5: Tidak Ada | V5: Tidak Ada | W5: Ada | X5: Ada | Y5: Ada | Z5: Tidak Ada | AA5: Tidak Ada | AB5: Sudah | AC5: Sudah | AD5: Sudah | AE5: Sudah | AF5: Belum | AG5: Sudah | AH5: Belum | AI5: Sudah | AJ5: Belum | AK5: Sudah | AL5: Sudah | AM5: Sudah | AO5: 151 | AP5: kekerasan seksual | AW5: v | AY5: terbatasnya SDM terlatih di UPTD PPA baik dari segi kualitas maupun kuantitas sehingga berdampak pada layanan yang diberikan pada masyarakat | AZ5: adanya koordinasi dan sinergitas antara lembaga/ instansi terkait yang memberikan layanan PPA dala bentuk kebijakan yang dimulai dari tingkat pusat selanjutnya ditindaklanjuti oleh pemerintah daerah | BA5: =countif(AB5:AL5,"Sudah") -> 8 | BB5: Ketersediaan Sumber Daya Manusia (SDM) | BG5: =IFERROR(__xludf.DUMMYFUNCTION("IF(REGEXMATCH(H5,""Peraturan Gubernur""),""Ada"",""Tidak Ada"")"),"Ada") -> Ada | BH5: =IF(N5 = "Belum Punya", "Tidak Ada", IF(N5 = "", "Tidak Menjawab", "Ada")) -> Ada | BI5: =IF(O5 = "Tidak Punya", "Tidak Ada", IF(O5 = "", "Tidak Menjawab", "Ada")) -> Ada | BJ5: =IF(AND(Q5="Ada",R5="Ada",S5="Ada"),"Lengkap","Tidak Lengkap") -> Lengkap | BK5: =IF(AND(T5="Ada",U5="Ada",V5="Ada",W5="Ada",X5="Ada",Y5="Ada"),"Lengkap","Tidak Lengkap") -> Tidak Lengkap
A6: 3 | B6: PROVINSI SUMATERA BARAT | C6: Par yono/ 08116681817 | D6: Jalan Batang Antokan No. 2 Padang | E6: 0751-447723 | F6: 08116612343 | G6: UPTD PPA | H6: Peraturan Gubernur Sumatera Barat Nomor 90 Tahun 2020 tentang Pembentukan Organisasi Dan Tata Kerja Unit Pelaksana Teknis Daerah Dinas Pemberdayaan Perempuan Dan Perlindungan Anak, Pengendalian Penduduk Dan Keluarga Berencana Provinsi Sumatera Barat yang merubah/mencabut Peraturan Gubernur Sumatera Barat Nomor 99 Tahun 2017 tentang Pembentukan UPTD PPA | I6: 2020 | J6: A | L6: uptdppa.sumbar@gmail.com | M6: Kasi 1 : Pengaduan Kasi 2 : Tindak Lanjut Kasubag TU | N6: MANDIRI | BA6: =countif(AB6:AL6,"Sudah") -> 0 | BG6: =IFERROR(__xludf.DUMMYFUNCTION("IF(REGEXMATCH(H6,""Peraturan Gubernur""),""Ada"",""Tidak Ada"")"),"Ada") -> Ada | BH6: =IF(N6 = "Belum Punya", "Tidak Ada", IF(N6 = "", "Tidak Menjawab", "Ada")) -> Ada | BI6: =IF(O6 = "Tidak Punya", "Tidak Ada", IF(O6 = "", "Tidak Menjawab", "Ada")) -> Tidak Menjawab | BJ6: =IF(AND(Q6="Ada",R6="Ada",S6="Ada"),"Lengkap","Tidak Lengkap") -> Tidak Lengkap | BK6: =IF(AND(T6="Ada",U6="Ada",V6="Ada",W6="Ada",X6="Ada",Y6="Ada"),"Lengkap","Tidak Lengkap") -> Tidak Lengkap
A7: 4 | B7: PROVINSI RIAU | C7: SRI NISMALA DEWI | D7: Jl. Diponegoro No.36A Komplek Gedung Dharmawanita Provinsi Riau | E7: - | F7: 811707098 | G7: UPT PPA | H7: Peraturan Gubernur Nomor 56 Tahun 2017 | I7: 2017 | J7: A | K7: HENDRI/08127074978 dan IIN/085365729988 | L7: Tindaklanjut.ppariau@gmail.com | M7: Kepala UPT PPA, Kasubbag Tata Usaha, Kepala Seksi Pengaduan, Kepala Seksi Tindak Lanjut | N7: Pinjam Gedung Selain Dinas PPPA | O7: Kamar/Ruangan di Kantor | P7: Saat ini UPT PPA Provinsi Riau menempati gedung kantor milik Pemerintah Provinsi Riau dibawah kewenangan aset Biro Umum Setda Provinsi Riau | Q7: Ada | R7: Ada | S7: Ada | T7: Ada | U7: Ada | V7: Ada | W7: Ada | X7: Ada | Y7: Ada | Z7: Tidak Ada | AA7: Tidak Ada | AB7: Sudah | AC7: Sudah | AD7: Sudah | AE7: Sudah | AF7: Sudah | AG7: Sudah | AH7: Sudah | AI7: Sudah | AJ7: Sudah | AK7: Sudah | AL7: Sudah | AM7: Dalam hal kebutuhan pemberdayaan ekonomi terhadap penyintas maupun keluarga UPT PPA Provinsi Riau sudah bekerjasama dengan Baznas, namun tidak semua penerima manfaat dapat menerima bantuan dari baznas, hanya penerima manfaat tertentu saja seperti harus beragama islam. UPT PPA Provinsi Riau juga mengalami hambatan karena belum banyaknya wadah/instansi/lembaga yang mendukung unruk pemberdayaan ekonomi penerima manfaat. dalam memfasilitasi pemberian layanan kesehatan terhadap korban kekerasan tidak bisa ditanggung oleh BPJS kesehatan, sementara UPT PPA Provinsi Riau juga belum bisa menganggarkan biaya layanan kesehatan yang tidak ditanggung oleh BPJS Kesehatan karena keterbatasan anggaran. | AN7: 153 kasus, 97 kasus anak dan 56 kasus perempuan. korban terdiri dari 111 anak, dan 56 korban perempuan | AO7: Kekerasan Seksual dengan jumlah 20 kasus perempuan dan 28 kasus anak pengasuhan anak sebanyak 28 kasus | AQ7: Berdasarkan Permendagri Nomor 12 tahun 2017 dengan nomenklatur UPT P2TP2A sesuai peraturan Gubernur Nomor 56 Tahun 2017 | AS7: Berdasarkan PermenPPPA nomor 4 Tahun 2018 nomenklatur menjadi UPT PPA sesuai dengan Pergub Nomor 85 Tahun 2019 | AW7: v | AY7: tidak tersedianya tenaga ahli yang stanby dalam melakukan pendampingan kasus seperti tenaga psikolog, peksos dan pendamping hukum sehingga jika kasus darurat akan memakan waktu sedikit lebih lama; Kompetensi SDM layanan di UPT PPA Provinsi harus din tingkatkan dalam berbagai aspek terutama dalam melakukan pelayanan. | AZ7: Mekanisme pelayanan bisa dilakukan dengan baik apabila lembaga/instansi/kementerian bisa melakukan koordinasi, integrasi dan kolaborasi dengan baik pula, mulai dari tahap pengaduan sampai tahap akhir (terminasi). masing-masing lembaga/instansi/kementerian bisa menambil peran dan melaksanakan tugas dan fungsinya dengan baik sesuai dengan kebutuhan korban | BA7: =countif(AB7:AL7,"Sudah") -> 11 | BG7: =IFERROR(__xludf.DUMMYFUNCTION("IF(REGEXMATCH(H7,""Peraturan Gubernur""),""Ada"",""Tidak Ada"")"),"Ada") -> Ada | BH7: =IF(N7 = "Belum Punya", "Tidak Ada", IF(N7 = "", "Tidak Menjawab", "Ada")) -> Ada | BI7: =IF(O7 = "Tidak Punya", "Tidak Ada", IF(O7 = "", "Tidak Menjawab", "Ada")) -> Ada | BJ7: =IF(AND(Q7="Ada",R7="Ada",S7="Ada"),"Lengkap","Tidak Lengkap") -> Lengkap | BK7: =IF(AND(T7="Ada",U7="Ada",V7="Ada",W7="Ada",X7="Ada",Y7="Ada"),"Lengkap","Tidak Lengkap") -> Lengkap
A8: 5 | B8: PROVINSI JAMBI | C8: Asi Noprini/ 081271506723 | D8: Jl. Jenderal A. Yani No 09, Telanaipura, Jambi | E8: - | F8: 8117455411 | G8: UPTD PPA | H8: Peraturan Gubernur Provinsi Jambi Nomor 61 Tahun 2018 | I8: 2018 | J8: A | K8: Nurhidayarti/ 08127305496 | L8: uptdppa.provjambi@gmail.com | M8: Kepala UPTD PPA, Kasubag TU, Kasi Pengaduan dan Kasi Tindak Lanjut | N8: BERGABUNG DENGAN KANTOR DINAS | O8: PINJAM PAKAI | Q8: Ada | R8: Ada | S8: Ada | T8: Tidak Ada | U8: Tidak Ada | V8: Tidak Ada | W8: Ada | X8: Ada | Y8: Ada | Z8: Tidak Ada | AA8: Ada | AB8: Sudah | AC8: Sudah | AD8: Sudah | AE8: Sudah | AF8: Sudah | AG8: Sudah | AH8: Sudah | AI8: Sudah | AJ8: Sudah | AK8: Sudah | AL8: Sudah | AN8: 134 | AO8: Kekerasan Seksual | AR8: V | BA8: =countif(AB8:AL8,"Sudah") -> 11 | BG8: =IFERROR(__xludf.DUMMYFUNCTION("IF(REGEXMATCH(H8,""Peraturan Gubernur""),""Ada"",""Tidak Ada"")"),"Ada") -> Ada | BH8: =IF(N8 = "Belum Punya", "Tidak Ada", IF(N8 = "", "Tidak Menjawab", "Ada")) -> Ada | BI8: =IF(O8 = "Tidak Punya", "Tidak Ada", IF(O8 = "", "Tidak Menjawab", "Ada")) -> Ada | BJ8: =IF(AND(Q8="Ada",R8="Ada",S8="Ada"),"Lengkap","Tidak Lengkap") -> Lengkap | BK8: =IF(AND(T8="Ada",U8="Ada",V8="Ada",W8="Ada",X8="Ada",Y8="Ada"),"Lengkap","Tidak Lengkap") -> Tidak Lengkap
A9: 6 | B9: PROVINSI SUMATERA SELATAN | C9: INDRA SURYA, SE.,M.M | D9: Jl. Ade Irma Nasution No. 1524, Kel. Sei Pangeran, Kec. Ilir Timur 1 Palembang | E9: 82177111299 | F9: 82177111299 | G9: UPTD PPA | H9: Peraturan Gubernur No. 54 Tahun 2020 | I9: 2020 | J9: A | K9: Amirudin, SH.,M.Si / 0853-6660-6151 | L9: amiruddin09127@gmail.com | M9: Kepala UPTD, Kassubag TU, Kasi Tindaklanjut, Kasi Penerima Pengaduan | N9: Bergabung dengan Kantor Dinas | O9: Tidak Punya | Q9: Tidak Ada | R9: Ada | S9: Ada | T9: Ada | U9: Tidak Ada | V9: Ada | W9: Ada | X9: Tidak Ada | Y9: Ada | Z9: Tidak Ada | AA9: Tidak Ada | AB9: Sudah | AC9: Sudah | AD9: Sudah | AE9: Sudah | AF9: Sudah | AG9: Sudah | AH9: Sudah | AI9: Sudah | AJ9: Sudah | AK9: Sudah | AL9: Sudah | AN9: 72 Kasus | AO9: Pelecehan Seksual dan KDRT | AT9: v | AY9: Kurangnya SDM | AZ9: Mekanisme yang dijalankan sudah efektif | BA9: =countif(AB9:AL9,"Sudah") -> 11 | BG9: =IFERROR(__xludf.DUMMYFUNCTION("IF(REGEXMATCH(H9,""Peraturan Gubernur""),""Ada"",""Tidak Ada"")"),"Ada") -> Ada | BH9: =IF(N9 = "Belum Punya", "Tidak Ada", IF(N9 = "", "Tidak Menjawab", "Ada")) -> Ada | BI9: =IF(O9 = "Tidak Punya", "Tidak Ada", IF(O9 = "", "Tidak Menjawab", "Ada")) -> Tidak Ada | BJ9: =IF(AND(Q9="Ada",R9="Ada",S9="Ada"),"Lengkap","Tidak Lengkap") -> Tidak Lengkap | BK9: =IF(AND(T9="Ada",U9="Ada",V9="Ada",W9="Ada",X9="Ada",Y9="Ada"),"Lengkap","Tidak Lengkap") -> Tidak Lengkap
A10: 7 | B10: PROVINSI BENGKULU | C10: Ekmaharti, SE | D10: Jalan Pembangunan No. 13, Telp 0736.21124 Padang Harapan Bengkulu | E10: 85839986880 | F10: WA : 085182905453, Web : e.rasa.bengkuluprov.go.id, FB : Rumah amanah Raflesia | G10: UPTD PPA | H10: Peraturan Gubernur Bengkulu Nomor 34 Tahun 2017 | I10: 2017 | J10: A | K10: 085839986880 / 0895336812677 | L10: uptdlayanan@gmail.com | M10: Kepala UPTD, Kasubag TU, kasi pelayanan, kasi Penjangkauan dan pendampingan kasus, | N10: Masih bergabung dengan Dinas | O10: Tidak Punya | P10: Pemerintah Daerah | Q10: Ada | R10: Ada | S10: Ada | T10: Ada | U10: Ada | V10: Ada | W10: Ada | X10: Ada | Y10: Ada | Z10: Ada | AA10: Tidak ada | AB10: Sudah | AC10: Sudah | AD10: Sudah | AE10: sudah | AF10: Sudah | AG10: Sudah | AH10: Belum | AI10: Sudah | AJ10: Belum | AK10: Sudah | AL10: Sudah | AM10: pengaduan dari masyarakat, penjangkuan korban, pengelolaan Kasus | AN10: 27 Kasus | AO10: KDRT | AQ10: v | BA10: =countif(AB10:AL10,"Sudah") -> 9 | BG10: =IFERROR(__xludf.DUMMYFUNCTION("IF(REGEXMATCH(H10,""Peraturan Gubernur""),""Ada"",""Tidak Ada"")"),"Ada") -> Ada | BH10: =IF(N10 = "Belum Punya", "Tidak Ada", IF(N10 = "", "Tidak Menjawab", "Ada")) -> Ada | BI10: =IF(O10 = "Tidak Punya", "Tidak Ada", IF(O10 = "", "Tidak Menjawab", "Ada")) -> Tidak Ada | BJ10: =IF(AND(Q10="Ada",R10="Ada",S10="Ada"),"Lengkap","Tidak Lengkap") -> Lengkap | BK10: =IF(AND(T10="Ada",U10="Ada",V10="Ada",W10="Ada",X10="Ada",Y10="Ada"),"Lengkap","Tidak Lengkap") -> Lengkap
A11: 8 | B11: PROVINSI LAMPUNG | C11: Ria Meylanie/08117216211 | D11: Jl. Puri Bersakih Blok EE 5 Taman Puri Way Halim, Bandar Lampung | E11: 0721 709600 | F11: 08117911120 | G11: UPTD PPA | H11: Peraturan Gubernur Lampung Nomor 10 Tahun 2020 tentang Pembentukan Organisasi dan Tata Kerja Unit Pelaksana Teknis Dinas (UPTD) pada Dinas Daerah Provinsi Lampung | I11: 2020 | J11: A | K11: Andres 085279792272 (Kasi Pengaduan) Julia Siti/ 081320501982 (Kasi Tindak Lanjut) | L11: indomanlampung@gmail.com | M11: 1. Kepala UPTD 2. Kasubbag TU 3. Kasi Pengaduan 4. Kasi Tindak lanjut 5. Tim Profesi | N11: MANDIRI | O11: SEWA/KONTRAK | Q11: Ada | R11: Ada | S11: Ada | T11: Ada | U11: Tidak Ada | V11: Tidak Ada | W11: Ada | X11: Ada | Y11: Ada | Z11: Tidak Ada | AA11: Tidak Ada | AB11: Sudah | AC11: Sudah | AD11: Sudah | AE11: Sudah | AF11: Sudah | AG11: Sudah | AH11: Sudah | AI11: Sudah | AJ11: Sudah | AK11: Sudah | AL11: Sudah | AM11: Psikolog Klinis (2) Konselor Hukum (2) Konselor Psikologi (2) | AN11: 231 (2024) | AO11: Kekerasan Terhadap Anak | AQ11: v | AW11: v | AY11: Faktor Eksternal : 1. Perbedaan pendapat terhadap pemahaman kasus 2. Stigma masyarakat 3. Kasus seringkali dianggap aib keluarga 4. Kurangnya pemahaman dari keluarga korban terkait proses hukum. Faktor Internal : 1. Keterbatasan anggaran 2. Kapasitas SDM | AZ11: 1. Penambahan anggaran. 2.Penempatan SDM yang kompeten 3. Sinergitas antar OPD terkait penanganan kekerasan pada perempuan dan anak | BA11: =countif(AB11:AL11,"Sudah") -> 11 | BB11: Stigma/Kesadaran Masyarakat akan Kekerasan | BC11: Ketersediaan Anggaran | BD11: Ketersediaan Sumber Daya Manusia (SDM) | BG11: =IFERROR(__xludf.DUMMYFUNCTION("IF(REGEXMATCH(H11,""Peraturan Gubernur""),""Ada"",""Tidak Ada"")"),"Ada") -> Ada | BH11: =IF(N11 = "Belum Punya", "Tidak Ada", IF(N11 = "", "Tidak Menjawab", "Ada")) -> Ada | BI11: =IF(O11 = "Tidak Punya", "Tidak Ada", IF(O11 = "", "Tidak Menjawab", "Ada")) -> Ada | BJ11: =IF(AND(Q11="Ada",R11="Ada",S11="Ada"),"Lengkap","Tidak Lengkap") -> Lengkap | BK11: =IF(AND(T11="Ada",U11="Ada",V11="Ada",W11="Ada",X11="Ada",Y11="Ada"),"Lengkap","Tidak Lengkap") -> Tidak Lengkap
A12: 9 | B12: PROVINSI KEP. BANGKA BELITUNG | C12: Wardahmuthar/08117113010 | D12: JL. Pulau Belitung Komplek Perkantoran dan Pemukiman Terpadu | E12: 0717-425517 | F12: 85314145959 | G12: UPTD PPA | H12: Peraturan Gubernur No. 12 Tahun 2021 | I12: 2021 | J12: A | K12: Syaifuddin / 085272270852 | L12: uptdppababel | M12: Kepala UPTD, Kasubbag TU, Kasi Pelayanan pengaduan, Informasi dan Kerjasama, Kasi Tindakan dan Rujukan | N12: Mandiri | O12: Sewa/Kontrak | P12: rencananya rumah perlindungan akan kita gabung dengan kantor UPTD PPA | Q12: Ada | R12: Ada | S12: Ada | T12: Tidak Ada | U12: Tidak Ada | V12: Tidak Ada | W12: Ada | X12: Tidak Ada | Y12: Tidak Ada | Z12: Tidak Ada | AA12: Tidak Ada | AB12: Sudah | AC12: Sudah | AD12: Belum | AE12: Sudah | AF12: Belum | AG12: Sudah | AH12: Belum | AI12: Sudah | AJ12: Belum | AK12: Sudah | AL12: Sudah | AM12: Koordinasi dan kolaborasi dengan instansi terkait | AN12: 352 | AO12: Kekerasan Seksual | AU12: v | AY12: korban tidak mempunyai akses untuk komunikasi (tidak punya HP) , lokasi tempat korban sulit di jangkau, tantangan dari pihak pelaku (masih keluarga dg APH) | AZ12: Prosedur yang singkat, agar korban cepat terlayani | BA12: =countif(AB12:AL12,"Sudah") -> 7 | BG12: =IFERROR(__xludf.DUMMYFUNCTION("IF(REGEXMATCH(H12,""Peraturan Gubernur""),""Ada"",""Tidak Ada"")"),"Ada") -> Ada | BH12: =IF(N12 = "Belum Punya", "Tidak Ada", IF(N12 = "", "Tidak Menjawab", "Ada")) -> Ada | BI12: =IF(O12 = "Tidak Punya", "Tidak Ada", IF(O12 = "", "Tidak Menjawab", "Ada")) -> Ada | BJ12: =IF(AND(Q12="Ada",R12="Ada",S12="Ada"),"Lengkap","Tidak Lengkap") -> Lengkap | BK12: =IF(AND(T12="Ada",U12="Ada",V12="Ada",W12="Ada",X12="Ada",Y12="Ada"),"Lengkap","Tidak Lengkap") -> Tidak Lengkap
A13: 10 | B13: PROVINSI KEPULAUAN RIAU | C13: Dra.Sandra Liza.Apt.M,Kes | D13: Jl.riau no 1 s.d 3 Tanjungpinang | E13: - | F13: 811771881 | G13: UPTD PPA | H13: Peraturan Gubernur Nomor 30 Tahun 2022 | I13: 2022 | J13: A | K13: 85763544786 | L13: nongjelex@gmail.com | M13: Kepala UPTD PPA, Kasubag TU, Kasi Penerima Pengaduan, Penjangkauan dan Identifikasi, Kasi Rehabilitasi Pemulangan dan Reintegrasi dan Kelompok Jabatan Struktural (PPPK) | N13: Mandiri | O13: Aset Pemda Dikelola Dinas PPPA | P13: - | Q13: Ada | R13: Ada | S13: Ada | T13: Ada | U13: Tidak Ada | V13: Tidak Ada | W13: Ada | X13: Ada | Y13: Tidak Ada | Z13: Tidak Ada | AA13: Tidak Ada | AB13: Sudah | AC13: Sudah | AD13: Sudah | AE13: Sudah | AF13: Sudah | AG13: Sudah | AH13: Belum | AI13: Sudah | AJ13: Sudah | AK13: Sudah | AL13: Sudah | AM13: pelayanan sudah termasuk UU TPKS | AN13: 114 kasus | AO13: TPPO | AQ13: v | AY13: korban sulit terbuka dalam memberikan pengaduan laporan | AZ13: berdasarkan UU PPA dan TKPS | BA13: =countif(AB13:AL13,"Sudah") -> 10 | BG13: =IFERROR(__xludf.DUMMYFUNCTION("IF(REGEXMATCH(H13,""Peraturan Gubernur""),""Ada"",""Tidak Ada"")"),"Ada") -> Ada | BH13: =IF(N13 = "Belum Punya", "Tidak Ada", IF(N13 = "", "Tidak Menjawab", "Ada")) -> Ada | BI13: =IF(O13 = "Tidak Punya", "Tidak Ada", IF(O13 = "", "Tidak Menjawab", "Ada")) -> Ada | BJ13: =IF(AND(Q13="Ada",R13="Ada",S13="Ada"),"Lengkap","Tidak Lengkap") -> Lengkap | BK13: =IF(AND(T13="Ada",U13="Ada",V13="Ada",W13="Ada",X13="Ada",Y13="Ada"),"Lengkap","Tidak Lengkap") -> Tidak Lengkap
A14: 11 | B14: PROVINSI DKI JAKARTA | C14: Leny Yunengsih (Plt. KA UPTD PPA) | D14: Jl. Raya Bekasi Timur KM.18, Jatinegara Kaum, Pulo Gadung, RT07/RW06, Jatinegara Kaum, Kota Jakarta Timur, DKI Jakarta | E14: (021) 47882898 | F14: 081317617622 | G14: UPT PPPA | H14: Peraturan Gubernur DKI Jakarta Nomor 397 Tahun 2016 tentang Pembentukan Organisasi dan Tata Kerja Pusat Pelayanan Terpadu Pemberdayaan Perempuan dan Anak Peraturan Gubernur DKI Jakarta Nomor 57 Tahun 2022 tentang Organisasi dan Tata Kerja Perangkat Daerah | I14: 2016 | J14: A | K14: Yuni/081280963351 (Kasubag TU) | L14: pppa@jakarta.go.id | M14: Kepala UPT, Subag TU, Satuan Pelaksana Pelayanan Pendampingan dan Pencegahan Kekerasan Perempuan dan Anak dan Sub Kelompok Jabatan Fungsional | N14: MANDIRI | O14: SEWA/KONTRAK | P14: Pemerintah Daerah | Q14: Ada | R14: Ada | S14: Ada | T14: Ada | U14: Ada | V14: Ada | W14: Ada | X14: Ada | Y14: Ada | Z14: Tidak Ada | AA14: Tidak Ada | AB14: Sudah | AC14: Sudah | AD14: Sudah | AE14: Sudah | AF14: Sudah | AG14: Sudah | AH14: Sudah | AI14: Sudah | AJ14: Sudah | AK14: Sudah | AL14: Sudah | AM14: Tersedia layanan penerimaan pengaduan, pengelolaan kasus, pendampingan korban, psikologi, hukum dan penampungan sementara berupa transit house maksimal 14 hari yang dikelola Dinas PPAPP melalui UPT PPPA dan safe house lebih dari 14 hari yang dikelola Dinsos DKI Jakarta | AN14: 2041 | AO14: Anak Korban Kekerasan Seksual / KTA Seksual | AP14: v | AY14: (1) Perbedaan perspektif penanganan KTP/A antar stakeholder; (2) Rumah Aman yang dapat mengakomodir kebutuhan khusus, contoh korban KDRT, TPPO, Disabilitas (3) Pemberdayaan ekonomi bagi korban KTP (4) Efektivitas layanan Reintegrasi Sosial / After Care kerjasama dengan para mitra (5) Peningkatan mutu dan kompetensi SDM | AZ14: (1) Peningkatan kerjasama program KtP/A dalam KSD antar Dinas dan Lembaga; (2) Tersedia penampungan sementara/ rumah aman yang mengakomodir kebutuhan spesifik korban KtP/A termasuk panduan/dasar kebijakan/pedoman layanan penampungan sementara dari Kemenpppa, contoh Permenpppa untuk Rumah SAPA; (3) Peningkatan kerjasama antara Pemerintah, Pihak Swasta, Masyarakat dan Badan PBB; (4) Peningkatan DAK untuk mendukung pemenuhan hak korban KtP/A (5) Peningkatan kapasitas bagi SDM | BA14: =countif(AB14:AL14,"Sudah") -> 11 | BB14: Rujukan Lanjutan dengan OPD Terkait | BC14: Ketersediaan Sarana dan Prasarana | BD14: Ketersediaan Sumber Daya Manusia (SDM) | BE14: Koordinasi/Jejaring | BG14: =IFERROR(__xludf.DUMMYFUNCTION("IF(REGEXMATCH(H14,""Peraturan Gubernur""),""Ada"",""Tidak Ada"")"),"Ada") -> Ada | BH14: =IF(N14 = "Belum Punya", "Tidak Ada", IF(N14 = "", "Tidak Menjawab", "Ada")) -> Ada | BI14: =IF(O14 = "Tidak Punya", "Tidak Ada", IF(O14 = "", "Tidak Menjawab", "Ada")) -> Ada | BJ14: =IF(AND(Q14="Ada",R14="Ada",S14="Ada"),"Lengkap","Tidak Lengkap") -> Lengkap | BK14: =IF(AND(T14="Ada",U14="Ada",V14="Ada",W14="Ada",X14="Ada",Y14="Ada"),"Lengkap","Tidak Lengkap") -> Lengkap
A15: 12 | B15: PROVINSI JAWA BARAT | C15: Utami Puspita Dewi, S.STP., M.Si/ 081221155235 | D15: Jl. L.L.RE Martadinata No. 2, Kota Bandung | E15: Tidak Ada | F15: 085222206777 | G15: UPTD PPA | H15: Peraturan Gubernur Jawa Barat Nomor 64 Tahun 2019 tentang Tugas Pokok, Fungsi, Rincian Tugas Unit dan Tata Kerja UPTD di Lingkungan DP3AKB Pemerintah Daerah Provinsi Jawa Barat | I15: 2019 | J15: A | K15: Utami Puspita Dewi, S.STP., M.Si/ 081221155235 | L15: uptdppa.dp3akb.jabar@gmail.com | M15: 1. Kepala UPTD 2. Kasubag TU 3. Kelompok Jabatan Fungsional | N15: MANDIRI | O15: MILIK SENDIRI | P15: Pemerintah Daerah | Q15: Ada | R15: Ada | S15: Ada | T15: Ada | U15: Tidak Ada | V15: Tidak Ada | W15: Tidak Ada | X15: Ada | Y15: Ada | Z15: Tidak Ada | AA15: Ada | AB15: Sudah | AC15: Sudah | AD15: Sudah | AE15: Sudah | AF15: Sudah | AG15: Sudah | AH15: Belum | AI15: Sudah | AJ15: Sudah | AK15: Sudah | AL15: Sudah | AM15: pengaduan dari masyarakat, penjangkuan korban, pengelolaan Kasus, Jika korban memerlukan pengamanan maka akan diberikan penampungan sementara di rumah aman | AN15: 948 | AO15: Kekerasan Terhadap Perempuan | AS15: v | BA15: =countif(AB15:AL15,"Sudah") -> 10 | BG15: =IFERROR(__xludf.DUMMYFUNCTION("IF(REGEXMATCH(H15,""Peraturan Gubernur""),""Ada"",""Tidak Ada"")"),"Ada") -> Ada | BH15: =IF(N15 = "Belum Punya", "Tidak Ada", IF(N15 = "", "Tidak Menjawab", "Ada")) -> Ada | BI15: =IF(O15 = "Tidak Punya", "Tidak Ada", IF(O15 = "", "Tidak Menjawab", "Ada")) -> Ada | BJ15: =IF(AND(Q15="Ada",R15="Ada",S15="Ada"),"Lengkap","Tidak Lengkap") -> Lengkap | BK15: =IF(AND(T15="Ada",U15="Ada",V15="Ada",W15="Ada",X15="Ada",Y15="Ada"),"Lengkap","Tidak Lengkap") -> Tidak Lengkap
A16: 13 | B16: PROVINSI JAWA TENGAH | C16: Eka Suprapti, ST, MM | D16: Jl. Puspowarno IV No. 11 Salaman Mloyo, Semarang Barat 50149 | E16: 85799664444 | F16: 85799664444 | G16: UPTD PPA Provinsi Jawa Tengah | H16: Peraturan Gubernur Jawa Tengah Nomor 15 Tahun 2023 tentang Organisasi dan Tata Kerja Dinas Pemberdayaan Perempuan, Perlindungan Anak, Pengendalian Penduduk, dan Keluarga Berencana Provinsi Jawa Tengah | I16: 2023 | J16: A | K16: Eka Suprapti, ST, MM/081325638917 | L16: uptdppajateng@gmail.com | M16: Kepala UPTD, Kasubag TU, Kelompok Jabatan Fungsional | N16: Mandiri | O16: Ada Melalui Kerja Sama | P16: - | Q16: Ada | R16: Ada | S16: Ada | T16: Ada | U16: Ada | V16: Ada | W16: Tidak Ada | X16: Tidak Ada | Y16: Tidak Ada | Z16: Tidak Ada | AA16: Tidak Ada | AB16: Sudah | AC16: Sudah | AD16: Sudah | AE16: Sudah | AF16: Sudah | AG16: Sudah | AH16: Belum | AI16: Sudah | AJ16: Sudah | AK16: Sudah | AL16: Sudah | AM16: pengaduan dari masyarakat, penjangkuan korban, pengelolaan Kasus, Jika korban memerlukan pengamanan maka akan diberikan penampungan sementara di rumah aman, jika korban memerlukan keberlangsungan pendidikan maka berkoordinasi dengan dinas pendidikan | AN16: 156 | AO16: Kekerasan seksual anak | AW16: v | AY16: Korban belum jujur dalam memberikan informasi kepada pendamping, Korban belum memiliki kemantapan dalam pengambilan keputusan, Belum semua jejaring memiliki perspektif yang sama dalam penanganan korban kekerasan | AZ16: Penanganan sesuai prioritas kebutuhan spesifik korban kekerasan | BA16: =countif(AB16:AL16,"Sudah") -> 10 | BG16: =IFERROR(__xludf.DUMMYFUNCTION("IF(REGEXMATCH(H16,""Peraturan Gubernur""),""Ada"",""Tidak Ada"")"),"Ada") -> Ada | BH16: =IF(N16 = "Belum Punya", "Tidak Ada", IF(N16 = "", "Tidak Menjawab", "Ada")) -> Ada | BI16: =IF(O16 = "Tidak Punya", "Tidak Ada", IF(O16 = "", "Tidak Menjawab", "Ada")) -> Ada | BJ16: =IF(AND(Q16="Ada",R16="Ada",S16="Ada"),"Lengkap","Tidak Lengkap") -> Lengkap | BK16: =IF(AND(T16="Ada",U16="Ada",V16="Ada",W16="Ada",X16="Ada",Y16="Ada"),"Lengkap","Tidak Lengkap") -> Tidak Lengkap
A17: 14 | B17: PROVINSI D I YOGYAKARTA | C17: Beni Kusambodo | D17: Jl. Tentara Rakyat Mataram No. 53 Yogyakarta | E17: (0274) 5030707 | G17: BALAI PPA | H17: Peraturan Gubernur (Pergub) Provinsi Daerah Istimewa Yogyakarta Nomor 11 Tahun 2022 tentang Pembentukan, Susunan Organisasi, Tugas, Fungsi, dan Tata Kerja Unit Pelaksana Teknis pada Dinas Pemberdayaan Perempuan, Perlindungan Anak, dan Pengendalian Penduduk | I17: 2022 | J17: B | K17: Beni Kusambodo/0815-7811-9696 | L17: bppa@jogjaprov.go.id ; bppadiy@gmail.com | M17: 1. Kepala Balai 2. Kasubag TU 3. Jabatan Fungsional | N17: MANDIRI | O17: MILIK SENDIRI | P17: Pemerintah Daerah | Q17: Ada | R17: Ada | S17: Tidak ada | T17: Tidak ada | U17: Ada | V17: Ada | W17: Ada | X17: Tidak ada | Y17: Tidak ada | Z17: Tidak ada | AA17: Tidak ada | AB17: Sudah | AC17: Sudah | AD17: Sudah | AE17: Sudah | AF17: Sudah | AG17: Sudah | AH17: Belum | AI17: Sudah | AJ17: Belum | AK17: Sudah | AL17: Belum | AN17: 47 (2024) | AO17: Kekerasan terhadap anak | AV17: v | AY17: Tidak tersedianya tenaga penerjemah untuk kasus yang melibatkan penyandang difabel, Kasus kekerasan seksual anak yang kemudian ortunya bersikeras tidak mau melanjutkan ke ranah hukum, Kasus tidak dapat dilanjutkan ke ranah hukum karena bukti dipandang penyidik masih kurang dan biasanya untuk kasus terkait siber | AZ17: Perlunya penilaian dan penerapan standarisasi layanan UPT, minimal layanan di Provinsi dahulu agar ada kesamaan pemahaman layanan dan agar korban menerima layanan yang sama dalam penanganan suatu kasus yang dirujuk | BA17: =countif(AB17:AL17,"Sudah") -> 8 | BB17: Ketersediaan Sumber Daya Manusia (SDM) | BC17: Stigma/Kesadaran Masyarakat akan Kekerasan | BG17: =IFERROR(__xludf.DUMMYFUNCTION("IF(REGEXMATCH(H17,""Peraturan Gubernur""),""Ada"",""Tidak Ada"")"),"Ada") -> Ada | BH17: =IF(N17 = "Belum Punya", "Tidak Ada", IF(N17 = "", "Tidak Menjawab", "Ada")) -> Ada | BI17: =IF(O17 = "Tidak Punya", "Tidak Ada", IF(O17 = "", "Tidak Menjawab", "Ada")) -> Ada | BJ17: =IF(AND(Q17="Ada",R17="Ada",S17="Ada"),"Lengkap","Tidak Lengkap") -> Tidak Lengkap | BK17: =IF(AND(T17="Ada",U17="Ada",V17="Ada",W17="Ada",X17="Ada",Y17="Ada"),"Lengkap","Tidak Lengkap") -> Tidak Lengkap
A18: 15 | B18: PROVINSI JAWA TIMUR | C18: Shinta Mawardiana/ 082244966000 | D18: Jl. Arjuno Nomor 88, Surabaya | E18: 0 | F18: 0895348771070 | G18: UPT PPA | H18: Peraturan Gubernur Jawa Timur Nomor 1 Tahun 2021 | I18: 2021 | J18: A | K18: Santiani/ 081246254083 | L18: uptdppa.dp3akprovjatim@gmail.com | M18: 1. Kepala UPT 2. Kasubag TU 3. Kasi Pengaduan, Penanganan dan Kedaruratan 4. Kasi Tindak Lanjut, Transisi dan Rehabilitasi | N18: MANDIRI | O18: MILIK SENDIRI | P18: Memberikan rumah perlindungan sementara ketika korban membutuhkan | Q18: Ada | R18: Ada | S18: Ada | T18: Ada | U18: Ada | V18: Ada | W18: Ada | X18: Ada | Y18: Tidak Ada | Z18: Tidak Ada | AA18: Ada | AB18: Sudah | AC18: Sudah | AD18: Sudah | AE18: Sudah | AF18: Sudah | AG18: Sudah | AH18: Sudah | AI18: Sudah | AJ18: Sudah | AK18: Sudah | AL18: Sudah | AM18: Catatan Kolom 35: Diberikan kepada korban kekerasan perempuan dan anak yang membutuhkan rumah aman selama maksimal 14 hari. Layanan yang diberikan meliputi konsultasi psikologis, konseling psikososial, layanan kesehatan dan bantuan hukum yang semunya dilakukan di Rumah Aman oleh petugas sesuai dengan kompetensi yang ada. | AU18: v | BA18: =countif(AB18:AL18,"Sudah") -> 11 | BG18: =IFERROR(__xludf.DUMMYFUNCTION("IF(REGEXMATCH(H18,""Peraturan Gubernur""),""Ada"",""Tidak Ada"")"),"Ada") -> Ada | BH18: =IF(N18 = "Belum Punya", "Tidak Ada", IF(N18 = "", "Tidak Menjawab", "Ada")) -> Ada | BI18: =IF(O18 = "Tidak Punya", "Tidak Ada", IF(O18 = "", "Tidak Menjawab", "Ada")) -> Ada | BJ18: =IF(AND(Q18="Ada",R18="Ada",S18="Ada"),"Lengkap","Tidak Lengkap") -> Lengkap | BK18: =IF(AND(T18="Ada",U18="Ada",V18="Ada",W18="Ada",X18="Ada",Y18="Ada"),"Lengkap","Tidak Lengkap") -> Tidak Lengkap
A19: 16 | B19: PROVINSI BANTEN | C19: Elis Pancaningsih,S.Sos,M.A | D19: Jalan Ki Ajurum No 4 Cipocok Jaya Kota Serang | E19: 0254 222418 | F19: 85129290316 | G19: UPTD PPA | H19: Peraturan Gubernur No 55 Tahun 2021 | I19: 2021 | J19: A | K19: 085286090400 ( Andri Humaedi) 085219951629 (Juhariah) | L19: uptd.ppa.banten@gmail.com | M19: Kepala UPTD, Kasubag TU, Kepala Seksi Pengaduan, Kepala Seksi Tindak Lanjut | N19: Mandiri | O19: Sewa/Kontrak | Q19: Ada | R19: Ada | S19: Ada | T19: Tidak Ada | U19: Tidak Ada | V19: Tidak Ada | W19: Tidak Ada | X19: Tidak Ada | Y19: Tidak Ada | Z19: Tidak Ada | AA19: Tidak Ada | AB19: Sudah | AC19: Sudah | AD19: Sudah | AE19: Sudah | AF19: Sudah | AG19: Sudah | AH19: Sudah | AI19: Sudah | AJ19: Sudah | AK19: Sudah | AL19: Sudah | AN19: 107 | AO19: Kekerasan Seksual Terhadap Anak | AU19: v | AY19: Penjemputan / Pemulangan Korban Lintas Provinsi | AZ19: Mekanisme Pelayanan Perempuan dan Anak Korban Kekerasan dibuat K/L secara terpadu di tingkat Pusat untuk kemudian diturunkan dan ditindaklanjuti di Daerah | BA19: =countif(AB19:AL19,"Sudah") -> 11 | BG19: =IFERROR(__xludf.DUMMYFUNCTION("IF(REGEXMATCH(H19,""Peraturan Gubernur""),""Ada"",""Tidak Ada"")"),"Ada") -> Ada | BH19: =IF(N19 = "Belum Punya", "Tidak Ada", IF(N19 = "", "Tidak Menjawab", "Ada")) -> Ada | BI19: =IF(O19 = "Tidak Punya", "Tidak Ada", IF(O19 = "", "Tidak Menjawab", "Ada")) -> Ada | BJ19: =IF(AND(Q19="Ada",R19="Ada",S19="Ada"),"Lengkap","Tidak Lengkap") -> Lengkap | BK19: =IF(AND(T19="Ada",U19="Ada",V19="Ada",W19="Ada",X19="Ada",Y19="Ada"),"Lengkap","Tidak Lengkap") -> Tidak Lengkap
A20: 17 | B20: PROVINSI BALI | C20: Luh Hety Vironika/ 081338552210 | D20: jl. Raya Pemongan no.209, denpasar | E20: (0361)4484315 | F20: 81338074883 | G20: UPTD PPA | H20: Peraturan Gubernur Bali Nomor 59 Tahun 2019 tentang Pembentukan Unit Pelaksana Teknis Daerah di Lingkungan Pemerintah Provinsi Bali | I20: 2019 | J20: A | K20: Luh Hety Vironika/ 081338552210, AA Utami Andayani/ 081338588906 | L20: uptdppaprovbali209@gmail.com | M20: Ka.UPTD PPA, Ka Subag TU, Kasi Penerimaan dan Klarifikasi, kasi Tindak Lanjut Kasus | N20: MANDIRI | O20: MILIK SENDIRI | P20: Pemerintah Daerah | Q20: Ada | R20: Ada | S20: Ada | T20: Ada | U20: Tidak Ada | V20: Ada | W20: Ada | X20: Ada | Y20: Ada | Z20: Tidak Ada | AA20: Tidak Ada | AB20: Sudah | AC20: Sudah | AD20: Sudah | AE20: Sudah | AF20: Sudah | AG20: Sudah | AH20: Sudah | AI20: Belum | AJ20: Sudah | AK20: Sudah | AL20: Sudah | AM20: Sudah | AN20: 524 | AO20: Kekerasan Terhadap Aperempuan | AP20: - | AQ20: 158 kasus | AR20: Fisik dan Psikis | AV20: v | BA20: =countif(AB20:AL20,"Sudah") -> 10 | BB20: Intervensi keluarga dan tidak mau dilaporkan ke kepolisian | BC20: Peningkatan koordinasi dengan lintas sektor, Pengembangan Kemampuan SDM Layanan dan Pengembangan SOP Layanan | BD20: 9 | BG20: =IFERROR(__xludf.DUMMYFUNCTION("IF(REGEXMATCH(H20,""Peraturan Gubernur""),""Ada"",""Tidak Ada"")"),"Ada") -> Ada | BH20: =IF(N20 = "Belum Punya", "Tidak Ada", IF(N20 = "", "Tidak Menjawab", "Ada")) -> Ada | BI20: =IF(O20 = "Tidak Punya", "Tidak Ada", IF(O20 = "", "Tidak Menjawab", "Ada")) -> Ada | BJ20: =IF(AND(Q20="Ada",R20="Ada",S20="Ada"),"Lengkap","Tidak Lengkap") -> Lengkap | BK20: =IF(AND(T20="Ada",U20="Ada",V20="Ada",W20="Ada",X20="Ada",Y20="Ada"),"Lengkap","Tidak Lengkap") -> Tidak Lengkap
A21: 18 | B21: PROVINSI NUSA TENGGARA BARAT | C21: Siti Eny Chaerany, SH | D21: Jalan Kaktus Nomor 6 Gomong Mataram | E21: 3707508946 | F21: 87881892220 | G21: UPTD PPA | H21: Peraturan Gubernur NTB Nomor 30 Tahun 2019 | I21: 2019 | J21: A | K21: 87881892220 | L21: uptdppaprovinsintb22@gmail.com | M21: Kepala UPTD, Kasubag TU, Kasi dan Kelompok Jabatan Fungsional | N21: Mandiri | O21: Kamar/Ruangan di Kantor | Q21: Ada | R21: Ada | S21: Ada | T21: Ada | U21: Tidak Ada | V21: Ada | W21: Ada | X21: Tidak Ada | Y21: Tidak Ada | Z21: Ada | AA21: Ada | AB21: Sudah | AC21: Sudah | AD21: Sudah | AE21: Sudah | AF21: Belum | AG21: Sudah | AH21: Belum | AI21: Sudah | AJ21: Belum | AK21: Sudah | AL21: Sudah | AN21: 80 kasus | AO21: kekerasan seksual | BA21: =countif(AB21:AL21,"Sudah") -> 8 | BG21: =IFERROR(__xludf.DUMMYFUNCTION("IF(REGEXMATCH(H21,""Peraturan Gubernur""),""Ada"",""Tidak Ada"")"),"Ada") -> Ada | BH21: =IF(N21 = "Belum Punya", "Tidak Ada", IF(N21 = "", "Tidak Menjawab", "Ada")) -> Ada | BI21: =IF(O21 = "Tidak Punya", "Tidak Ada", IF(O21 = "", "Tidak Menjawab", "Ada")) -> Ada | BJ21: =IF(AND(Q21="Ada",R21="Ada",S21="Ada"),"Lengkap","Tidak Lengkap") -> Lengkap | BK21: =IF(AND(T21="Ada",U21="Ada",V21="Ada",W21="Ada",X21="Ada",Y21="Ada"),"Lengkap","Tidak Lengkap") -> Tidak Lengkap
A22: 19 | B22: PROVINSI NUSA TENGGARA TIMUR | C22: Saleha H. Wongso, SE, MM | D22: Jl Beringin No. 1 Kelurahan Fontein Kecamatan Kota Raja Kota Kupang, Provinsi NTT | E22: 81236079933 | F22: 8111129129 | G22: UPTD PPA | H22: Peraturan Gubernur NTT Nomor 49 Tahun 2022 | I22: 2022 | J22: A | K22: 82144222630 | L22: megasidik25@gmail.com | M22: Kepala UPTD, Kasubag Tata Usaha, Kepala Seksi Pengaduan, Kepala Seksi Tindak Lanjut dan Kelompok Jabatan Fungsional | N22: Mandiri | O22: Milik Sendiri | P22: Gedung milik Pemerintah Provinsi NTT dan dibangun menggunakan APBD Provinsi NTT Tahun 2025 | Q22: Ada | R22: Ada | S22: Ada | T22: Ada | U22: Ada | V22: Ada | W22: Ada | X22: Ada | Y22: Ada | Z22: Ada | AA22: Ada | AB22: Sudah | AC22: Sudah | AD22: Sudah | AE22: Sudah | AF22: Sudah | AG22: Sudah | AH22: Sudah | AI22: Sudah | AJ22: Sudah | AK22: Sudah | AL22: Sudah | AN22: 398 | AO22: Psikis | AV22: v | AY22: Terbatasnya anggaran, terbatasnya sarana prasarana | AZ22: Mekanisme rujukan kasus secara online antar lintas daerah dan kewenangan | BA22: =countif(AB22:AL22,"Sudah") -> 11 | BG22: =IFERROR(__xludf.DUMMYFUNCTION("IF(REGEXMATCH(H22,""Peraturan Gubernur""),""Ada"",""Tidak Ada"")"),"Ada") -> Ada | BH22: =IF(N22 = "Belum Punya", "Tidak Ada", IF(N22 = "", "Tidak Menjawab", "Ada")) -> Ada | BI22: =IF(O22 = "Tidak Punya", "Tidak Ada", IF(O22 = "", "Tidak Menjawab", "Ada")) -> Ada | BJ22: =IF(AND(Q22="Ada",R22="Ada",S22="Ada"),"Lengkap","Tidak Lengkap") -> Lengkap | BK22: =IF(AND(T22="Ada",U22="Ada",V22="Ada",W22="Ada",X22="Ada",Y22="Ada"),"Lengkap","Tidak Lengkap") -> Lengkap
A23: 20 | B23: PROVINSI KALIMANTAN BARAT | C23: Nur Latifah/081345581234 | D23: Jalan Sultan Abdurrahman No. 101 Pontianak | E23: 0561 8102130 | F23: 082254080013 | G23: UPT PPA Provinsi Kalimantan Barat | H23: Peraturan Gubernur (Pergub) Provinsi Kalimantan Barat Nomor 101 Tahun 2020 tentang Pembentukan, Susunan Organisasi, Tugas dan Fungsi serta Tata Kerja Unit Pelaksana Teknis Perlindungan Perempuan dan Anak Provinsi Kalimantan Barat | I23: 2020 | J23: A | K23: Nur Latifah/081345581234 | L23: uptppa.provkalbar1@gmail.com | M23: Kepala UPTD, Kasubag TU dan Kelompok jabatan fungsional | N23: BERGABUNG DENGAN KANTOR DINAS | O23: MILIK SENDIRI | P23: Pemerintah Daerah | Q23: Ada | R23: Tidak Ada | S23: Tidak Ada | T23: Tidak Ada | U23: Tidak Ada | V23: Tidak Ada | W23: Tidak Ada | X23: Tidak Ada | Y23: Tidak Ada | Z23: Tidak Ada | AA23: Tidak Ada | AB23: Sudah | AC23: Sudah | AD23: Sudah | AE23: Sudah | AF23: Sudah | AG23: Sudah | AH23: Sudah | AI23: Sudah | AJ23: Sudah | AK23: Sudah | AL23: Sudah | AM23: pengaduan dari masyarakat, penjangkuan korban, pengelolaan Kasus, Jika korban memerlukan pengamanan maka akan diberikan penampungan sementara di rumah aman | AN23: 41 | AO23: Kekerasan terhadap anak | AT23: v | AY23: koordinasi antar lembaga belum efektif | AZ23: layanan terintegrasi | BA23: =countif(AB23:AL23,"Sudah") -> 11 | BG23: =IFERROR(__xludf.DUMMYFUNCTION("IF(REGEXMATCH(H23,""Peraturan Gubernur""),""Ada"",""Tidak Ada"")"),"Ada") -> Ada | BH23: =IF(N23 = "Belum Punya", "Tidak Ada", IF(N23 = "", "Tidak Menjawab", "Ada")) -> Ada | BI23: =IF(O23 = "Tidak Punya", "Tidak Ada", IF(O23 = "", "Tidak Menjawab", "Ada")) -> Ada | BJ23: =IF(AND(Q23="Ada",R23="Ada",S23="Ada"),"Lengkap","Tidak Lengkap") -> Tidak Lengkap | BK23: =IF(AND(T23="Ada",U23="Ada",V23="Ada",W23="Ada",X23="Ada",Y23="Ada"),"Lengkap","Tidak Lengkap") -> Tidak Lengkap
A24: 21 | B24: PROVINSI KALIMANTAN TENGAH | C24: Jumrah,S.ST.,M.AP | D24: Jl.Brigjen Katamso No. 11 | E24: - | F24: 8115201515 | G24: UPT PPA | H24: Peraturan Gubernur Nomor 2019 dan Peraturan Gubernur Nomor 48 Tahun 2023 | I24: 2019 | J24: A | K24: Rensi, M.Psi | L24: uptppa.kalteng.go.id | M24: Kepala UPT PPA, Kasubag TU, Kasie Pengaduan,Kasie Tindak lanjut, dan Kelompol Jabatan Fungsional | N24: Bergabung dengan Kantor Dinas | O24: Sewa/Kontrak | P24: - | Q24: Ada | R24: Ada | S24: Ada | T24: Ada | U24: Tidak Ada | V24: Tidak Ada | W24: Ada | X24: Tidak Ada | Y24: Tidak Ada | Z24: Tidak Ada | AA24: Ada | AB24: Sudah | AC24: Sudah | AD24: Sudah | AE24: Sudah | AF24: Sudah | AG24: Sudah | AH24: Sudah | AI24: Sudah | AJ24: Sudah | AK24: Sudah | AL24: Sudah | AN24: 64 kasus | AO24: Kekerasan Seksual | AS24: v | AW24: v | AY24: Keterbatasan SDM dan sarana prasarana | AZ24: Mekanisme administrasi dan birokrasi untuk penanganan kasus lintas provinsi agar dapat lebih cepat dalam penanganan. | BA24: =countif(AB24:AL24,"Sudah") -> 11 | BG24: =IFERROR(__xludf.DUMMYFUNCTION("IF(REGEXMATCH(H24,""Peraturan Gubernur""),""Ada"",""Tidak Ada"")"),"Ada") -> Ada | BH24: =IF(N24 = "Belum Punya", "Tidak Ada", IF(N24 = "", "Tidak Menjawab", "Ada")) -> Ada | BI24: =IF(O24 = "Tidak Punya", "Tidak Ada", IF(O24 = "", "Tidak Menjawab", "Ada")) -> Ada | BJ24: =IF(AND(Q24="Ada",R24="Ada",S24="Ada"),"Lengkap","Tidak Lengkap") -> Lengkap | BK24: =IF(AND(T24="Ada",U24="Ada",V24="Ada",W24="Ada",X24="Ada",Y24="Ada"),"Lengkap","Tidak Lengkap") -> Tidak Lengkap
A25: 22 | B25: PROVINSI KALIMANTAN SELATAN | C25: Drs. Musyridyansyah, M. Si | D25: Jl. Batu Tiban No.39, Tlk. Dalam, Kec. Banjarmasin Tengah, Kota Banjarmasin, Kalimantan Selatan 70115 | E25: 5114242128 | F25: 81253098883 | G25: UPTD Perlindungan Perempuan dan Anak Provinsi Kalimantan Selatan | H25: Peraturan Gubernur (Pergub) Provinsi Kalimantan Selatan Nomor 73 Tahun 2019 tentang Pembentukan, Organisasi, Dan Tata Kerja Unit Pelaksana Teknis Daerah Perlindungan Perempuan Dan Anak Pada Dinas Pemberdayaan Perempuan Dan Perlindungan Anak Provinsi Kalimantan Selatan | I25: 2019 | J25: A | K25: Ernawati (Kasubbag TU)/081251195092 | L25: ernawati.hertonie@gmail.com | M25: Kepala UPTD, Kasubag TU, Kasi Pengaduan, Kasi Tindak Lanjut dan Kelompok Jabatan Fungsional | N25: Mandiri | O25: Tidak Punya | Q25: Ada | R25: Ada | S25: Ada | T25: Tidak Ada | U25: Tidak Ada | V25: Tidak Ada | W25: Ada | X25: Ada | Y25: Ada | Z25: Tidak Ada | AA25: Tidak Ada | AB25: Sudah | AC25: Sudah | AD25: Sudah | AE25: Sudah | AF25: Belum | AG25: Sudah | AH25: Belum | AI25: Sudah | AJ25: Belum | AK25: Sudah | AL25: Sudah | AM25: Dari 11 Layanan yang sesuai dengan peraturan di atas saat ini UPTD PPA memenuhi 9 Layanan secara mandiri sedangkan 3 layanan yang terdiri dari layanan psikososial, rehabilitasi sosial, pemberdayaan sosial, dan reintegrasi sosial, layanan kebutuhan pemberdayaan ekonomi, dan layanan kebutuhan korban penyandang disabilitas bekerjasama dengan Dinas dan Lembaga terkait. | AN25: 49 Kasus | AO25: Kekerasan Seksual dan Kekerasan Psikis | AS25: v | AY25: Klien kurang kooperatif, sulitnya akses, kurangnya pemahaman tentang Undang-undang Tindak Pidana Kekerasan Seksual dari pihak kepolisian dan kejaksaan serta jumlah SDM yang kurang. | AZ25: Bangunan kantor yang terstandarisasi baik dari segi ruangan, fasilitas, dan SDM yang terlatih dibidangnya. | BA25: =countif(AB25:AL25,"Sudah") -> 8 | BG25: =IFERROR(__xludf.DUMMYFUNCTION("IF(REGEXMATCH(H25,""Peraturan Gubernur""),""Ada"",""Tidak Ada"")"),"Ada") -> Ada | BH25: =IF(N25 = "Belum Punya", "Tidak Ada", IF(N25 = "", "Tidak Menjawab", "Ada")) -> Ada | BI25: =IF(O25 = "Tidak Punya", "Tidak Ada", IF(O25 = "", "Tidak Menjawab", "Ada")) -> Tidak Ada | BJ25: =IF(AND(Q25="Ada",R25="Ada",S25="Ada"),"Lengkap","Tidak Lengkap") -> Lengkap | BK25: =IF(AND(T25="Ada",U25="Ada",V25="Ada",W25="Ada",X25="Ada",Y25="Ada"),"Lengkap","Tidak Lengkap") -> Tidak Lengkap
